Workbook

Sheet daily
A2: RECTO MEMORIAL NATIONAL HIGH SCHOOL
A3: Brgy. Quipot, Tiaong, Quezon
A5: STATEMENT OF OPERATIONS
A6: For the Period of NOVEMBER 2025
A7: (ALL CANTEEN)
A9: DAILY TRNASACTION
A10: MONTH | B10: WAGES | C10: SSS | D10: Office Supplies | E10: Store Supplies | F10: Storage Expenses | G10: Delivery Charge | H10: Repair | I10: Water | J10: PURCHASES | K10: Spoilage | L10: TOTAL Expenses | M10: GROSS SALES | N10: NET SALES
A11: January | L11: =SUM(B11:K11) -> 0 | N11: =SUM(M11-L11) -> 0
A12: Febuary | L12: =SUM(B12:K12) -> 0 | N12: =SUM(M12-L12) -> 0
A13: March | L13: =SUM(B13:K13) -> 0 | N13: =SUM(M13-L13) -> 0
A14: Arpril | L14: =SUM(B14:K14) -> 0 | N14: =SUM(M14-L14) -> 0
A15: May | L15: =SUM(B15:K15) -> 0 | N15: =SUM(M15-L15) -> 0
A16: June | L16: =SUM(B16:K16) -> 0 | N16: =SUM(M16-L16) -> 0
A17: July | L17: =SUM(B17:K17) -> 0 | N17: =SUM(M17-L17) -> 0
A18: August | L18: =SUM(B18:K18) -> 0 | N18: =SUM(M18-L18) -> 0
A19: September | L19: =SUM(B19:K19) -> 0 | N19: =SUM(M19-L19) -> 0
A20: October | L20: =SUM(B20:K20) -> 0 | N20: =SUM(M20-L20) -> 0
A21: November | L21: =SUM(B21:K21) -> 0 | N21: =SUM(M21-L21) -> 0
A22: December | L22: =SUM(B22:K22) -> 0 | N22: =SUM(M22-L22) -> 0
B23: =SUM(B11:C22) -> 0 | C23: =SUM(C11:C22) -> 0 | D23: =SUM(E11:E18) -> 0 | E23: =SUM(E11:E22) -> 0 | F23: =SUM(F11:F22) -> 0 | G23: =SUM(G11:G22) -> 0 | H23: =SUM(H11:H22) -> 0 | I23: =SUM(I11:I22) -> 0 | J23: =SUM(J11:J22) -> 0 | K23: =SUM(K11:K22) -> 0 | L23: =SUM(L11:L22) -> 0 | ... N23: =SUM(N11:N22) -> 0
B25: Prepared by:
B27: JASMIN M. DIMAUNAHAN
B28: SSHT I - TLE DEPARTMENT
B30: Audited by:
C32: RICKY B. ENRIQUEZ | L32: ODESSA B. MANGUIAT
C33: FSA PRESIDENT | L33: SSHT VI - MATH DEPARTMENT
C34: MEMBER | L34: CHAIRMAN

Sheet so1
A1: RECTO MEMORIAL NATIONAL HIGH SCHOOL
A2: Brgy. Quipot, Tiaong, Quezon
A4: STATEMENT OF OPERATIONS
A5: For the Period of NOVEMBER 2025
A6: (ALL CANTEEN)
D7: Current Year | E7: Previous Year
A9: REVENUES
B10: Net Sales
C11: Sales (Gross) | D11: =daily!M23 -> 0 | E11: 1164828
C12: Sales Returns and Allowances | D12: 0 | E12: 0
C13: Sales Discounts | D13: 0 | E13: 0
D15: =SUM(D9:D14) -> 0 | E15: =SUM(E9:E14) -> 1164828
B16: Cost of Sales
C17: Purchases | D17: =daily!J23 -> 0 | E17: 842318
C18: Purchase Returns and Allowances | D18: 0 | E18: 0
C19: Purchase Discounts | D19: 0 | E19: 0
C20: Freight In | D20: 0 | E20: 0
C21: Inventory | E21: 42570
B22: GROSS PROFIT | D22: =D15-D17-D21 -> 0 | E22: =SUM(E15-E17-E21) -> 279940
B23: Add: Other Operating Income | D23: 0 | E23: 0
B24: GROSS INCOME FROM OPERATIONS | D24: =SUM(D22:D23) -> 0 | E24: =SUM(E22:E23) -> 279940
A26: EXPENSES
B27: SELLING COSTS
C28: Salaries and Wages | D28: =daily!B23 -> 0 | E28: 123000
C29: Employees' Benefits | D29: 0 | E29: 0
C30: SSS/ECC/Philhealth/Pag-ibig Contributions | D30: =daily!C23 -> 0 | E30: 4005
C31: Officers' Honorarium and Allowances | D31: 0 | E31: 0
C32: Office Supplies | D32: =daily!D23 -> 0 | E32: 0
C33: Store Supplies | D33: =daily!E23 -> 0 | E33: 18176
C34: Storage/Warehousing Expense | D34: 0 | E34: 0
C35: Power, Light and Water | D35: =daily!I23 -> 0 | E35: 0
C36: Travel and Transportation | D36: 0 | E36: 0
C37: Insurance | D37: 0 | E37: 0
C38: Royalties | D38: 0 | E38: 0
C39: Repairs and Maintenance | D39: =daily!H23 -> 0 | E39: 0
C40: Rental | D40: 0 | E40: 0
C41: Taxes and Licenses | D41: 0 | E41: 0
C42: Communication Expense | D42: 0 | E42: 0
C43: Representation Expense | D43: 0 | E43: 0
C44: Advertising and Promotion | D44: 0 | E44: 0
...

Sheet so2
A1: RECTO MEMORIAL NATIONAL HIGH SCHOOL
A2: Brgy. Quipot, Tiaong, Quezon
A4: STATEMENT OF OPERATIONS
A5: For the Period of NOVEMBER 2025
A6: (ALL CANTEEN)
D7: Current Year | E7: Previous Year
B10: ADMINISTRATIVE COSTS
C11: Salaries and Wages | D11: 0 | E11: 0
C12: Employees' Benefits | D12: 0 | E12: 0
C13: SSS/ECC/Philhealth/Pag-ibig Contributions | D13: 0 | E13: 0
C14: Officers' Honorarium and Allowances | D14: 0 | E14: 0
C15: Office Supplies | D15: 0 | E15: 0
C16: Storage/Warehousing Expense | D16: 0 | E16: 0
C17: Power, Light and Water | D17: 0 | E17: 0
C18: Travel and Transportation | D18: 0 | E18: 0
C19: Depreciation and Amortization | D19: 0 | E19: 0
C20: Insurance | D20: 0 | E20: 0
C21: Repairs and Maintenance | D21: 0 | E21: 0
C22: Rental | D22: 0 | E22: 0
... C30: Privision for Probable Losses and Accounts Receivables | D30: 0 | E30: 0
B31: Total Administrative Costs | D31: =SUM(D11:D30) -> 0 | E31: =SUM(E11:E30) -> 0
B32: TOTAL EXPENSES | D32: =-'so1'!D51-'so2'!D31 -> 0 | E32: =-'so1'!E51-'so2'!E31 -> -145181
A33: NET INCOME DERIVED FROM OPERATIONS | D33: =SUM('so1'!D24+'so2'!D32) -> 0 | E33: =SUM('so1'!E24+'so2'!E32) -> 134759
B35: Prepared by:
B37: JASMIN M. DIMAUNAHAN
B38: SSHT I - TLE DEPARTMENT
B40: Audited by:
C42: RICKY B. ENRIQUEZ | D42: ODESSA B. MANGUIAT
C43: FSA PRESIDENT | D43: SSHT VI - MATH DEPARTMENT
C44: MEMBER | D44: CHAIRMAN

Sheet net_income
A1: RECTO MEMORIAL NATIONAL HIGH SCHOOL
A2: Brgy. Quipot, Tiaong, Quezon
A4: STATEMENT OF OPERATIONS
A5: For the Period of NOVEMBER 2025
A6: (ALL CANTEEN)
D7: Current Year | E7: Previous Year
B9: UTILIZATION OF NET INCOME
B11: Suplementary Feeding Program for Undernourished
B12: Pupils/Students | C12: 0.35 | D12: ='so2'!D33*net_income!C12 -> 0 | E12: ='so2'!E33*net_income!C12 -> 47165.65
B13: School Clinic Fund | C13: 0.05 | D13: ='so2'!D33*net_income!C13 -> 0 | E13: ='so2'!E33*net_income!C13 -> 6737.95
B14: Faculty and Student Development Fund | C14: 0.15 | D14: ='so2'!D33*net_income!C14 -> 0 | E14: ='so2'!E33*net_income!C14 -> 20213.85
B15: H.E. Instructional Fund | C15: 0.1 | D15: ='so2'!D33*net_income!C15 -> 0 | E15: ='so2'!E33*net_income!C15 -> 13475.9
B16: Schools Operations Fund | C16: 0.25 | D16: ='so2'!D33*net_income!C16 -> 0 | E16: ='so2'!E33*net_income!C16 -> 33689.75
B17: Revolving Capital | C17: 0.1 | D17: ='so2'!D33*net_income!C17 -> 0 | E17: ='so2'!E33*net_income!C17 -> 13475.9
B19: TOTAL UTILIZATION OF NET INCOME | C19: 1 | D19: =SUM(D12:D17) -> 0 | E19: =SUM(E12:E18) -> 134759
B22: Prepared by:
B24: JASMIN M. DIMAUNAHAN
B25: SSHT I - TLE DEPARTMENT
B28: Audited by:
B31: RICKY B. ENRIQUEZ
B32: FSA PRESIDENT
B33: MEMBER
B36: ODESSA B. MANGUIAT
B37: SSHT VI - MATH DEPARTMENT
B38: CHAIRMAN

Sheet financial
A1: RECTO MEMORIAL NATIONAL HIGH SCHOOL
A2: Brgy. Quipot, Tiaong, Quezon
A4: STATEMENT OF FINANCIAL CONDITION
A5: For the Period of NOVEMBER 2025
A6: (ALL CANTEEN)
D7: Current Year | E7: Previous Year
A9: ASSETS
B10: Cash and cash equivalents | D10: =net_income!D19 -> 0 | E10: 0
B11: Account Receivables | D11: 0 | E11: 0
B12: Inventory | D12: 0 | E12: 0
B13: Investments | D13: 0 | E13: 0
B14: Property, plant and equipment at cost | D14: 0 | E14: 0
B15: Less: Accumulated depreciation | D15: 0 | E15: 0
A16: TOTAL ASSETS | D16: =SUM(D10:D15) -> 0 | E16: =SUM(E10:E15) -> 0
A18: LIABILITIES
B19: Trade Payable | D19: 0 | E19: 0
B20: Interest Payable | D20: 0 | E20: 0
B21: Income Taxes Payable | D21: 0 | E21: 0
B22: Other Payables | D22: 0 | E22: 0
B23: TOTAL LIABILITIES | D23: =SUM(D19:D22) -> 0 | E23: =SUM(E19:E22) -> 0
A25: EQUITY
B26: School Revolving Capital | D26: 0 | E26: 0
B27: Add: Net Income Derived from Operation of Canteen | D27: ='so2'!D33 -> 0 | E27: ='so2'!E33 -> 134759
B28: TOTAL EQUITY | D28: =SUM(D26:D27) -> 0 | E28: =SUM(E26:E27) -> 134759
A29: TOTAL LIABILITIES AND EQUITY | D29: =SUM(D23+D28) -> 0 | E29: =SUM(E23+E28) -> 134759
B31: Prepared by:
B33: JASMIN M. DIMAUNAHAN
B34: SSHT I - TLE DEPARTMENT
B37: Audited by:
B40: RICKY B. ENRIQUEZ
B41: FSA PRESIDENT
B42: MEMBER
B45: ODESSA B. MANGUIAT
B46: SSHT VI - MATH DEPARTMENT
B47: CHAIRMAN
